2018-05-26 17:40:00.452 +01:00 [Information] Microsoft.AspNetCore.Hosting.Internal.WebHost: Request starting HTTP/1.1 POST http://localhost:50439/ application/x-www-form-urlencoded 409
2018-05-26 17:40:00.455 +01:00 [Information] Plato.Hosting.Web.Routing.PlatoRouterMiddleware: Begin Routing Request
2018-05-26 17:40:00.458 +01:00 [Information] Plato.Repositories.Settings.SettingRepository: Selecting all settings
2018-05-26 17:40:00.501 +01:00 [Information] Microsoft.AspNetCore.Mvc.Internal.ControllerActionInvoker: Executing action method Plato.SetUp.Controllers.SetUpController.Index (Plato.SetUp) with arguments (Plato.SetUp.ViewModels.SetUpViewModel) - ModelState is Valid
2018-05-26 17:40:00.505 +01:00 [Information] Plato.SetUp.Controllers.SetUpController: Index POST action on SetUp controller invoked!
2018-05-26 17:40:00.508 +01:00 [Information] Plato.SetUp.Controllers.SetUpController: Beginning call to SetUpAsync
2018-05-26 17:40:22.127 +01:00 [Information] Plato.Repositories.Settings.SettingRepository: Selecting all settings
2018-05-26 17:40:22.295 +01:00 [Information] Plato.Repositories.Settings.SettingRepository: Selecting all settings
2018-05-26 17:40:22.335 +01:00 [Information] Plato.Repositories.Settings.SettingRepository: Updating settings with id: 1
2018-05-26 17:40:22.385 +01:00 [Information] Plato.Repositories.Settings.SettingRepository: Selecting setting with id: 1
2018-05-26 17:40:22.388 +01:00 [Information] Plato.Repositories.Settings.SettingRepository: Selecting all settings
2018-05-26 17:41:54.965 +01:00 [Information] Plato.SetUp.Controllers.SetUpController: Set-up of tennet 'Plato30' failed with the following errors...
2018-05-26 17:41:54.967 +01:00 [Information] Plato.SetUp.Controllers.SetUpController: There is already an object named 'plato30_Settings' in the database.    at Plato.Data.DbContext.<>c.<ConfigureInternal>b__13_0(Object sender, DbExceptionEventArgs args) in C:\Users\Ryan\Source\Repos\plato\src\Plato.Data\DbContext.cs:line 82
   at Plato.Data.Providers.SqlProvider.HandleException(Exception x) in C:\Users\Ryan\Source\Repos\plato\src\Plato.Data\Providers\SqlProvider.cs:line 387
   at Plato.Data.Providers.SqlProvider.<ExecuteAsync>d__36.MoveNext() in C:\Users\Ryan\Source\Repos\plato\src\Plato.Data\Providers\SqlProvider.cs:line 265
--- End of stack trace from previous location where exception was thrown ---
   at System.Runtime.ExceptionServices.ExceptionDispatchInfo.Throw()
   at System.Runtime.CompilerServices.TaskAwaiter.HandleNonSuccessAndDebuggerNotification(Task task)
   at System.Runtime.CompilerServices.TaskAwaiter`1.GetResult()
   at Plato.Data.DbContext.<ExecuteAsync>d__19.MoveNext() in C:\Users\Ryan\Source\Repos\plato\src\Plato.Data\DbContext.cs:line 153
--- End of stack trace from previous location where exception was thrown ---
   at System.Runtime.ExceptionServices.ExceptionDispatchInfo.Throw()
   at System.Runtime.CompilerServices.TaskAwaiter.HandleNonSuccessAndDebuggerNotification(Task task)
   at System.Runtime.CompilerServices.TaskAwaiter`1.GetResult()
   at Plato.Data.Schemas.SchemaBuilder.<ApplySchemaAsync>d__22.MoveNext() in C:\Users\Ryan\Source\Repos\plato\src\Plato.Data.Schemas\SchemaBuilder.cs:line 276
2018-05-26 17:41:54.970 +01:00 [Information] Plato.SetUp.Controllers.SetUpController: There is already an object named 'plato30_SelectSettings' in the database.    at Plato.Data.DbContext.<>c.<ConfigureInternal>b__13_0(Object sender, DbExceptionEventArgs args) in C:\Users\Ryan\Source\Repos\plato\src\Plato.Data\DbContext.cs:line 82
   at Plato.Data.Providers.SqlProvider.HandleException(Exception x) in C:\Users\Ryan\Source\Repos\plato\src\Plato.Data\Providers\SqlProvider.cs:line 387
   at Plato.Data.Providers.SqlProvider.<ExecuteAsync>d__36.MoveNext() in C:\Users\Ryan\Source\Repos\plato\src\Plato.Data\Providers\SqlProvider.cs:line 265
--- End of stack trace from previous location where exception was thrown ---
   at System.Runtime.ExceptionServices.ExceptionDispatchInfo.Throw()
   at System.Runtime.CompilerServices.TaskAwaiter.HandleNonSuccessAndDebuggerNotification(Task task)
   at System.Runtime.CompilerServices.TaskAwaiter`1.GetResult()
   at Plato.Data.DbContext.<ExecuteAsync>d__19.MoveNext() in C:\Users\Ryan\Source\Repos\plato\src\Plato.Data\DbContext.cs:line 153
--- End of stack trace from previous location where exception was thrown ---
   at System.Runtime.ExceptionServices.ExceptionDispatchInfo.Throw()
   at System.Runtime.CompilerServices.TaskAwaiter.HandleNonSuccessAndDebuggerNotification(Task task)
   at System.Runtime.CompilerServices.TaskAwaiter`1.GetResult()
   at Plato.Data.Schemas.SchemaBuilder.<ApplySchemaAsync>d__22.MoveNext() in C:\Users\Ryan\Source\Repos\plato\src\Plato.Data.Schemas\SchemaBuilder.cs:line 276
2018-05-26 17:41:54.972 +01:00 [Information] Plato.SetUp.Controllers.SetUpController: There is already an object named 'plato30_SelectSettingById' in the database.    at Plato.Data.DbContext.<>c.<ConfigureInternal>b__13_0(Object sender, DbExceptionEventArgs args) in C:\Users\Ryan\Source\Repos\plato\src\Plato.Data\DbContext.cs:line 82
   at Plato.Data.Providers.SqlProvider.HandleException(Exception x) in C:\Users\Ryan\Source\Repos\plato\src\Plato.Data\Providers\SqlProvider.cs:line 387
   at Plato.Data.Providers.SqlProvider.<ExecuteAsync>d__36.MoveNext() in C:\Users\Ryan\Source\Repos\plato\src\Plato.Data\Providers\SqlProvider.cs:line 265
--- End of stack trace from previous location where exception was thrown ---
   at System.Runtime.ExceptionServices.ExceptionDispatchInfo.Throw()
   at System.Runtime.CompilerServices.TaskAwaiter.HandleNonSuccessAndDebuggerNotification(Task task)
   at System.Runtime.CompilerServices.TaskAwaiter`1.GetResult()
   at Plato.Data.DbContext.<ExecuteAsync>d__19.MoveNext() in C:\Users\Ryan\Source\Repos\plato\src\Plato.Data\DbContext.cs:line 153
--- End of stack trace from previous location where exception was thrown ---
   at System.Runtime.ExceptionServices.ExceptionDispatchInfo.Throw()
   at System.Runtime.CompilerServices.TaskAwaiter.HandleNonSuccessAndDebuggerNotification(Task task)
   at System.Runtime.CompilerServices.TaskAwaiter`1.GetResult()
   at Plato.Data.Schemas.SchemaBuilder.<ApplySchemaAsync>d__22.MoveNext() in C:\Users\Ryan\Source\Repos\plato\src\Plato.Data.Schemas\SchemaBuilder.cs:line 276
2018-05-26 17:41:54.974 +01:00 [Information] Plato.SetUp.Controllers.SetUpController: There is already an object named 'plato30_DeleteSettingById' in the database.    at Plato.Data.DbContext.<>c.<ConfigureInternal>b__13_0(Object sender, DbExceptionEventArgs args) in C:\Users\Ryan\Source\Repos\plato\src\Plato.Data\DbContext.cs:line 82
   at Plato.Data.Providers.SqlProvider.HandleException(Exception x) in C:\Users\Ryan\Source\Repos\plato\src\Plato.Data\Providers\SqlProvider.cs:line 387
   at Plato.Data.Providers.SqlProvider.<ExecuteAsync>d__36.MoveNext() in C:\Users\Ryan\Source\Repos\plato\src\Plato.Data\Providers\SqlProvider.cs:line 265
--- End of stack trace from previous location where exception was thrown ---
   at System.Runtime.ExceptionServices.ExceptionDispatchInfo.Throw()
   at System.Runtime.CompilerServices.TaskAwaiter.HandleNonSuccessAndDebuggerNotification(Task task)
   at System.Runtime.CompilerServices.TaskAwaiter`1.GetResult()
   at Plato.Data.DbContext.<ExecuteAsync>d__19.MoveNext() in C:\Users\Ryan\Source\Repos\plato\src\Plato.Data\DbContext.cs:line 153
--- End of stack trace from previous location where exception was thrown ---
   at System.Runtime.ExceptionServices.ExceptionDispatchInfo.Throw()
   at System.Runtime.CompilerServices.TaskAwaiter.HandleNonSuccessAndDebuggerNotification(Task task)
   at System.Runtime.CompilerServices.TaskAwaiter`1.GetResult()
   at Plato.Data.Schemas.SchemaBuilder.<ApplySchemaAsync>d__22.MoveNext() in C:\Users\Ryan\Source\Repos\plato\src\Plato.Data.Schemas\SchemaBuilder.cs:line 276
2018-05-26 17:41:54.976 +01:00 [Information] Plato.SetUp.Controllers.SetUpController: There is already an object named 'plato30_InsertUpdateSetting' in the database.    at Plato.Data.DbContext.<>c.<ConfigureInternal>b__13_0(Object sender, DbExceptionEventArgs args) in C:\Users\Ryan\Source\Repos\plato\src\Plato.Data\DbContext.cs:line 82
   at Plato.Data.Providers.SqlProvider.HandleException(Exception x) in C:\Users\Ryan\Source\Repos\plato\src\Plato.Data\Providers\SqlProvider.cs:line 387
   at Plato.Data.Providers.SqlProvider.<ExecuteAsync>d__36.MoveNext() in C:\Users\Ryan\Source\Repos\plato\src\Plato.Data\Providers\SqlProvider.cs:line 265
--- End of stack trace from previous location where exception was thrown ---
   at System.Runtime.ExceptionServices.ExceptionDispatchInfo.Throw()
   at System.Runtime.CompilerServices.TaskAwaiter.HandleNonSuccessAndDebuggerNotification(Task task)
   at System.Runtime.CompilerServices.TaskAwaiter`1.GetResult()
   at Plato.Data.DbContext.<ExecuteAsync>d__19.MoveNext() in C:\Users\Ryan\Source\Repos\plato\src\Plato.Data\DbContext.cs:line 153
--- End of stack trace from previous location where exception was thrown ---
   at System.Runtime.ExceptionServices.ExceptionDispatchInfo.Throw()
   at System.Runtime.CompilerServices.TaskAwaiter.HandleNonSuccessAndDebuggerNotification(Task task)
   at System.Runtime.CompilerServices.TaskAwaiter`1.GetResult()
   at Plato.Data.Schemas.SchemaBuilder.<ApplySchemaAsync>d__22.MoveNext() in C:\Users\Ryan\Source\Repos\plato\src\Plato.Data.Schemas\SchemaBuilder.cs:line 276
2018-05-26 17:41:54.978 +01:00 [Information] Plato.SetUp.Controllers.SetUpController: There is already an object named 'plato30_SelectSettingByKey' in the database.    at Plato.Data.DbContext.<>c.<ConfigureInternal>b__13_0(Object sender, DbExceptionEventArgs args) in C:\Users\Ryan\Source\Repos\plato\src\Plato.Data\DbContext.cs:line 82
   at Plato.Data.Providers.SqlProvider.HandleException(Exception x) in C:\Users\Ryan\Source\Repos\plato\src\Plato.Data\Providers\SqlProvider.cs:line 387
   at Plato.Data.Providers.SqlProvider.<ExecuteAsync>d__36.MoveNext() in C:\Users\Ryan\Source\Repos\plato\src\Plato.Data\Providers\SqlProvider.cs:line 265
--- End of stack trace from previous location where exception was thrown ---
   at System.Runtime.ExceptionServices.ExceptionDispatchInfo.Throw()
   at System.Runtime.CompilerServices.TaskAwaiter.HandleNonSuccessAndDebuggerNotification(Task task)
   at System.Runtime.CompilerServices.TaskAwaiter`1.GetResult()
   at Plato.Data.DbContext.<ExecuteAsync>d__19.MoveNext() in C:\Users\Ryan\Source\Repos\plato\src\Plato.Data\DbContext.cs:line 153
--- End of stack trace from previous location where exception was thrown ---
   at System.Runtime.ExceptionServices.ExceptionDispatchInfo.Throw()
   at System.Runtime.CompilerServices.TaskAwaiter.HandleNonSuccessAndDebuggerNotification(Task task)
   at System.Runtime.CompilerServices.TaskAwaiter`1.GetResult()
   at Plato.Data.Schemas.SchemaBuilder.<ApplySchemaAsync>d__22.MoveNext() in C:\Users\Ryan\Source\Repos\plato\src\Plato.Data.Schemas\SchemaBuilder.cs:line 276
2018-05-26 17:41:54.980 +01:00 [Information] Plato.SetUp.Controllers.SetUpController: There is already an object named 'plato30_Users' in the database.    at Plato.Data.DbContext.<>c.<ConfigureInternal>b__13_0(Object sender, DbExceptionEventArgs args) in C:\Users\Ryan\Source\Repos\plato\src\Plato.Data\DbContext.cs:line 82
   at Plato.Data.Providers.SqlProvider.HandleException(Exception x) in C:\Users\Ryan\Source\Repos\plato\src\Plato.Data\Providers\SqlProvider.cs:line 387
   at Plato.Data.Providers.SqlProvider.<ExecuteAsync>d__36.MoveNext() in C:\Users\Ryan\Source\Repos\plato\src\Plato.Data\Providers\SqlProvider.cs:line 265
--- End of stack trace from previous location where exception was thrown ---
   at System.Runtime.ExceptionServices.ExceptionDispatchInfo.Throw()
   at System.Runtime.CompilerServices.TaskAwaiter.HandleNonSuccessAndDebuggerNotification(Task task)
   at System.Runtime.CompilerServices.TaskAwaiter`1.GetResult()
   at Plato.Data.DbContext.<ExecuteAsync>d__19.MoveNext() in C:\Users\Ryan\Source\Repos\plato\src\Plato.Data\DbContext.cs:line 153
--- End of stack trace from previous location where exception was thrown ---
   at System.Runtime.ExceptionServices.ExceptionDispatchInfo.Throw()
   at System.Runtime.CompilerServices.TaskAwaiter.HandleNonSuccessAndDebuggerNotification(Task task)
   at System.Runtime.CompilerServices.TaskAwaiter`1.GetResult()
   at Plato.Data.Schemas.SchemaBuilder.<ApplySchemaAsync>d__22.MoveNext() in C:\Users\Ryan\Source\Repos\plato\src\Plato.Data.Schemas\SchemaBuilder.cs:line 276
2018-05-26 17:41:54.983 +01:00 [Information] Plato.SetUp.Controllers.SetUpController: There is already an object named 'plato30_SelectUsers' in the database.    at Plato.Data.DbContext.<>c.<ConfigureInternal>b__13_0(Object sender, DbExceptionEventArgs args) in C:\Users\Ryan\Source\Repos\plato\src\Plato.Data\DbContext.cs:line 82
   at Plato.Data.Providers.SqlProvider.HandleException(Exception x) in C:\Users\Ryan\Source\Repos\plato\src\Plato.Data\Providers\SqlProvider.cs:line 387
   at Plato.Data.Providers.SqlProvider.<ExecuteAsync>d__36.MoveNext() in C:\Users\Ryan\Source\Repos\plato\src\Plato.Data\Providers\SqlProvider.cs:line 265
--- End of stack trace from previous location where exception was thrown ---
   at System.Runtime.ExceptionServices.ExceptionDispatchInfo.Throw()
   at System.Runtime.CompilerServices.TaskAwaiter.HandleNonSuccessAndDebuggerNotification(Task task)
   at System.Runtime.CompilerServices.TaskAwaiter`1.GetResult()
   at Plato.Data.DbContext.<ExecuteAsync>d__19.MoveNext() in C:\Users\Ryan\Source\Repos\plato\src\Plato.Data\DbContext.cs:line 153
--- End of stack trace from previous location where exception was thrown ---
   at System.Runtime.ExceptionServices.ExceptionDispatchInfo.Throw()
   at System.Runtime.CompilerServices.TaskAwaiter.HandleNonSuccessAndDebuggerNotification(Task task)
   at System.Runtime.CompilerServices.TaskAwaiter`1.GetResult()
   at Plato.Data.Schemas.SchemaBuilder.<ApplySchemaAsync>d__22.MoveNext() in C:\Users\Ryan\Source\Repos\plato\src\Plato.Data.Schemas\SchemaBuilder.cs:line 276
2018-05-26 17:41:54.985 +01:00 [Information] Plato.SetUp.Controllers.SetUpController: There is already an object named 'plato30_SelectUserById' in the database.    at Plato.Data.DbContext.<>c.<ConfigureInternal>b__13_0(Object sender, DbExceptionEventArgs args) in C:\Users\Ryan\Source\Repos\plato\src\Plato.Data\DbContext.cs:line 82
   at Plato.Data.Providers.SqlProvider.HandleException(Exception x) in C:\Users\Ryan\Source\Repos\plato\src\Plato.Data\Providers\SqlProvider.cs:line 387
   at Plato.Data.Providers.SqlProvider.<ExecuteAsync>d__36.MoveNext() in C:\Users\Ryan\Source\Repos\plato\src\Plato.Data\Providers\SqlProvider.cs:line 265
--- End of stack trace from previous location where exception was thrown ---
   at System.Runtime.ExceptionServices.ExceptionDispatchInfo.Throw()
   at System.Runtime.CompilerServices.TaskAwaiter.HandleNonSuccessAndDebuggerNotification(Task task)
   at System.Runtime.CompilerServices.TaskAwaiter`1.GetResult()
   at Plato.Data.DbContext.<ExecuteAsync>d__19.MoveNext() in C:\Users\Ryan\Source\Repos\plato\src\Plato.Data\DbContext.cs:line 153
--- End of stack trace from previous location where exception was thrown ---
   at System.Runtime.ExceptionServices.ExceptionDispatchInfo.Throw()
   at System.Runtime.CompilerServices.TaskAwaiter.HandleNonSuccessAndDebuggerNotification(Task task)
   at System.Runtime.CompilerServices.TaskAwaiter`1.GetResult()
   at Plato.Data.Schemas.SchemaBuilder.<ApplySchemaAsync>d__22.MoveNext() in C:\Users\Ryan\Source\Repos\plato\src\Plato.Data.Schemas\SchemaBuilder.cs:line 276
2018-05-26 17:41:54.987 +01:00 [Information] Plato.SetUp.Controllers.SetUpController: There is already an object named 'plato30_DeleteUserById' in the database.    at Plato.Data.DbContext.<>c.<ConfigureInternal>b__13_0(Object sender, DbExceptionEventArgs args) in C:\Users\Ryan\Source\Repos\plato\src\Plato.Data\DbContext.cs:line 82
   at Plato.Data.Providers.SqlProvider.HandleException(Exception x) in C:\Users\Ryan\Source\Repos\plato\src\Plato.Data\Providers\SqlProvider.cs:line 387
   at Plato.Data.Providers.SqlProvider.<ExecuteAsync>d__36.MoveNext() in C:\Users\Ryan\Source\Repos\plato\src\Plato.Data\Providers\SqlProvider.cs:line 265
--- End of stack trace from previous location where exception was thrown ---
   at System.Runtime.ExceptionServices.ExceptionDispatchInfo.Throw()
   at System.Runtime.CompilerServices.TaskAwaiter.HandleNonSuccessAndDebuggerNotification(Task task)
   at System.Runtime.CompilerServices.TaskAwaiter`1.GetResult()
   at Plato.Data.DbContext.<ExecuteAsync>d__19.MoveNext() in C:\Users\Ryan\Source\Repos\plato\src\Plato.Data\DbContext.cs:line 153
--- End of stack trace from previous location where exception was thrown ---
   at System.Runtime.ExceptionServices.ExceptionDispatchInfo.Throw()
   at System.Runtime.CompilerServices.TaskAwaiter.HandleNonSuccessAndDebuggerNotification(Task task)
   at System.Runtime.CompilerServices.TaskAwaiter`1.GetResult()
   at Plato.Data.Schemas.SchemaBuilder.<ApplySchemaAsync>d__22.MoveNext() in C:\Users\Ryan\Source\Repos\plato\src\Plato.Data.Schemas\SchemaBuilder.cs:line 276
2018-05-26 17:41:54.989 +01:00 [Information] Plato.SetUp.Controllers.SetUpController: There is already an object named 'plato30_InsertUpdateUser' in the database.    at Plato.Data.DbContext.<>c.<ConfigureInternal>b__13_0(Object sender, DbExceptionEventArgs args) in C:\Users\Ryan\Source\Repos\plato\src\Plato.Data\DbContext.cs:line 82
   at Plato.Data.Providers.SqlProvider.HandleException(Exception x) in C:\Users\Ryan\Source\Repos\plato\src\Plato.Data\Providers\SqlProvider.cs:line 387
   at Plato.Data.Providers.SqlProvider.<ExecuteAsync>d__36.MoveNext() in C:\Users\Ryan\Source\Repos\plato\src\Plato.Data\Providers\SqlProvider.cs:line 265
--- End of stack trace from previous location where exception was thrown ---
   at System.Runtime.ExceptionServices.ExceptionDispatchInfo.Throw()
   at System.Runtime.CompilerServices.TaskAwaiter.HandleNonSuccessAndDebuggerNotification(Task task)
   at System.Runtime.CompilerServices.TaskAwaiter`1.GetResult()
   at Plato.Data.DbContext.<ExecuteAsync>d__19.MoveNext() in C:\Users\Ryan\Source\Repos\plato\src\Plato.Data\DbContext.cs:line 153
--- End of stack trace from previous location where exception was thrown ---
   at System.Runtime.ExceptionServices.ExceptionDispatchInfo.Throw()
   at System.Runtime.CompilerServices.TaskAwaiter.HandleNonSuccessAndDebuggerNotification(Task task)
   at System.Runtime.CompilerServices.TaskAwaiter`1.GetResult()
   at Plato.Data.Schemas.SchemaBuilder.<ApplySchemaAsync>d__22.MoveNext() in C:\Users\Ryan\Source\Repos\plato\src\Plato.Data.Schemas\SchemaBuilder.cs:line 276
2018-05-26 17:41:54.991 +01:00 [Information] Plato.SetUp.Controllers.SetUpController: There is already an object named 'plato30_SelectUserByEmail' in the database.    at Plato.Data.DbContext.<>c.<ConfigureInternal>b__13_0(Object sender, DbExceptionEventArgs args) in C:\Users\Ryan\Source\Repos\plato\src\Plato.Data\DbContext.cs:line 82
   at Plato.Data.Providers.SqlProvider.HandleException(Exception x) in C:\Users\Ryan\Source\Repos\plato\src\Plato.Data\Providers\SqlProvider.cs:line 387
   at Plato.Data.Providers.SqlProvider.<ExecuteAsync>d__36.MoveNext() in C:\Users\Ryan\Source\Repos\plato\src\Plato.Data\Providers\SqlProvider.cs:line 265
--- End of stack trace from previous location where exception was thrown ---
   at System.Runtime.ExceptionServices.ExceptionDispatchInfo.Throw()
   at System.Runtime.CompilerServices.TaskAwaiter.HandleNonSuccessAndDebuggerNotification(Task task)
   at System.Runtime.CompilerServices.TaskAwaiter`1.GetResult()
   at Plato.Data.DbContext.<ExecuteAsync>d__19.MoveNext() in C:\Users\Ryan\Source\Repos\plato\src\Plato.Data\DbContext.cs:line 153
--- End of stack trace from previous location where exception was thrown ---
   at System.Runtime.ExceptionServices.ExceptionDispatchInfo.Throw()
   at System.Runtime.CompilerServices.TaskAwaiter.HandleNonSuccessAndDebuggerNotification(Task task)
   at System.Runtime.CompilerServices.TaskAwaiter`1.GetResult()
   at Plato.Data.Schemas.SchemaBuilder.<ApplySchemaAsync>d__22.MoveNext() in C:\Users\Ryan\Source\Repos\plato\src\Plato.Data.Schemas\SchemaBuilder.cs:line 276
2018-05-26 17:41:54.994 +01:00 [Information] Plato.SetUp.Controllers.SetUpController: There is already an object named 'plato30_SelectUserByUserName' in the database.    at Plato.Data.DbContext.<>c.<ConfigureInternal>b__13_0(Object sender, DbExceptionEventArgs args) in C:\Users\Ryan\Source\Repos\plato\src\Plato.Data\DbContext.cs:line 82
   at Plato.Data.Providers.SqlProvider.HandleException(Exception x) in C:\Users\Ryan\Source\Repos\plato\src\Plato.Data\Providers\SqlProvider.cs:line 387
   at Plato.Data.Providers.SqlProvider.<ExecuteAsync>d__36.MoveNext() in C:\Users\Ryan\Source\Repos\plato\src\Plato.Data\Providers\SqlProvider.cs:line 265
--- End of stack trace from previous location where exception was thrown ---
   at System.Runtime.ExceptionServices.ExceptionDispatchInfo.Throw()
   at System.Runtime.CompilerServices.TaskAwaiter.HandleNonSuccessAndDebuggerNotification(Task task)
   at System.Runtime.CompilerServices.TaskAwaiter`1.GetResult()
   at Plato.Data.DbContext.<ExecuteAsync>d__19.MoveNext() in C:\Users\Ryan\Source\Repos\plato\src\Plato.Data\DbContext.cs:line 153
--- End of stack trace from previous location where exception was thrown ---
   at System.Runtime.ExceptionServices.ExceptionDispatchInfo.Throw()
   at System.Runtime.CompilerServices.TaskAwaiter.HandleNonSuccessAndDebuggerNotification(Task task)
   at System.Runtime.CompilerServices.TaskAwaiter`1.GetResult()
   at Plato.Data.Schemas.SchemaBuilder.<ApplySchemaAsync>d__22.MoveNext() in C:\Users\Ryan\Source\Repos\plato\src\Plato.Data.Schemas\SchemaBuilder.cs:line 276
2018-05-26 17:41:54.996 +01:00 [Information] Plato.SetUp.Controllers.SetUpController: There is already an object named 'plato30_SelectUserByUserNameNormalized' in the database.    at Plato.Data.DbContext.<>c.<ConfigureInternal>b__13_0(Object sender, DbExceptionEventArgs args) in C:\Users\Ryan\Source\Repos\plato\src\Plato.Data\DbContext.cs:line 82
   at Plato.Data.Providers.SqlProvider.HandleException(Exception x) in C:\Users\Ryan\Source\Repos\plato\src\Plato.Data\Providers\SqlProvider.cs:line 387
   at Plato.Data.Providers.SqlProvider.<ExecuteAsync>d__36.MoveNext() in C:\Users\Ryan\Source\Repos\plato\src\Plato.Data\Providers\SqlProvider.cs:line 265
--- End of stack trace from previous location where exception was thrown ---
   at System.Runtime.ExceptionServices.ExceptionDispatchInfo.Throw()
   at System.Runtime.CompilerServices.TaskAwaiter.HandleNonSuccessAndDebuggerNotification(Task task)
   at System.Runtime.CompilerServices.TaskAwaiter`1.GetResult()
   at Plato.Data.DbContext.<ExecuteAsync>d__19.MoveNext() in C:\Users\Ryan\Source\Repos\plato\src\Plato.Data\DbContext.cs:line 153
--- End of stack trace from previous location where exception was thrown ---
   at System.Runtime.ExceptionServices.ExceptionDispatchInfo.Throw()
   at System.Runtime.CompilerServices.TaskAwaiter.HandleNonSuccessAndDebuggerNotification(Task task)
   at System.Runtime.CompilerServices.TaskAwaiter`1.GetResult()
   at Plato.Data.Schemas.SchemaBuilder.<ApplySchemaAsync>d__22.MoveNext() in C:\Users\Ryan\Source\Repos\plato\src\Plato.Data.Schemas\SchemaBuilder.cs:line 276
2018-05-26 17:41:54.998 +01:00 [Information] Plato.SetUp.Controllers.SetUpController: There is already an object named 'plato30_SelectUserByEmailAndPassword' in the database.    at Plato.Data.DbContext.<>c.<ConfigureInternal>b__13_0(Object sender, DbExceptionEventArgs args) in C:\Users\Ryan\Source\Repos\plato\src\Plato.Data\DbContext.cs:line 82
   at Plato.Data.Providers.SqlProvider.HandleException(Exception x) in C:\Users\Ryan\Source\Repos\plato\src\Plato.Data\Providers\SqlProvider.cs:line 387
   at Plato.Data.Providers.SqlProvider.<ExecuteAsync>d__36.MoveNext() in C:\Users\Ryan\Source\Repos\plato\src\Plato.Data\Providers\SqlProvider.cs:line 265
--- End of stack trace from previous location where exception was thrown ---
   at System.Runtime.ExceptionServices.ExceptionDispatchInfo.Throw()
   at System.Runtime.CompilerServices.TaskAwaiter.HandleNonSuccessAndDebuggerNotification(Task task)
   at System.Runtime.CompilerServices.TaskAwaiter`1.GetResult()
   at Plato.Data.DbContext.<ExecuteAsync>d__19.MoveNext() in C:\Users\Ryan\Source\Repos\plato\src\Plato.Data\DbContext.cs:line 153
--- End of stack trace from previous location where exception was thrown ---
   at System.Runtime.ExceptionServices.ExceptionDispatchInfo.Throw()
   at System.Runtime.CompilerServices.TaskAwaiter.HandleNonSuccessAndDebuggerNotification(Task task)
   at System.Runtime.CompilerServices.TaskAwaiter`1.GetResult()
   at Plato.Data.Schemas.SchemaBuilder.<ApplySchemaAsync>d__22.MoveNext() in C:\Users\Ryan\Source\Repos\plato\src\Plato.Data.Schemas\SchemaBuilder.cs:line 276
2018-05-26 17:41:55.001 +01:00 [Information] Plato.SetUp.Controllers.SetUpController: Could not find stored procedure 'plato30_plato_sp_InsertUpdateUserSecret'.    at Plato.Data.DbContext.<>c.<ConfigureInternal>b__13_0(Object sender, DbExceptionEventArgs args) in C:\Users\Ryan\Source\Repos\plato\src\Plato.Data\DbContext.cs:line 82
   at Plato.Data.Providers.SqlProvider.HandleException(Exception x) in C:\Users\Ryan\Source\Repos\plato\src\Plato.Data\Providers\SqlProvider.cs:line 387
   at Plato.Data.Providers.SqlProvider.ExecuteScalarAsync[T](String sql, Object[] args) in C:\Users\Ryan\Source\Repos\plato\src\Plato.Data\Providers\SqlProvider.cs:line 209
   at Plato.Data.DbContext.<ExecuteScalarAsync>d__17`1.MoveNext() in C:\Users\Ryan\Source\Repos\plato\src\Plato.Data\DbContext.cs:line 135
--- End of stack trace from previous location where exception was thrown ---
   at System.Runtime.ExceptionServices.ExceptionDispatchInfo.Throw()
   at System.Runtime.CompilerServices.TaskAwaiter.HandleNonSuccessAndDebuggerNotification(Task task)
   at System.Runtime.CompilerServices.TaskAwaiter`1.GetResult()
   at Plato.Repositories.Users.UserSecretRepository.<InsertUpdateInternal>d__6.MoveNext() in C:\Users\Ryan\Source\Repos\plato\src\Plato.Repositories\Users\UserSecretRepository.cs:line 94
--- End of stack trace from previous location where exception was thrown ---
   at System.Runtime.ExceptionServices.ExceptionDispatchInfo.Throw()
   at System.Runtime.CompilerServices.TaskAwaiter.HandleNonSuccessAndDebuggerNotification(Task task)
   at System.Runtime.CompilerServices.TaskAwaiter`1.GetResult()
   at Plato.Repositories.Users.UserSecretRepository.<InsertUpdateAsync>d__4.MoveNext() in C:\Users\Ryan\Source\Repos\plato\src\Plato.Repositories\Users\UserSecretRepository.cs:line 43
--- End of stack trace from previous location where exception was thrown ---
   at System.Runtime.ExceptionServices.ExceptionDispatchInfo.Throw()
   at System.Runtime.CompilerServices.TaskAwaiter.HandleNonSuccessAndDebuggerNotification(Task task)
   at System.Runtime.CompilerServices.TaskAwaiter`1.GetResult()
   at Plato.Repositories.Users.UserRepository.<InsertUpdateAsync>d__7.MoveNext() in C:\Users\Ryan\Source\Repos\plato\src\Plato.Repositories\Users\UserRepository.cs:line 90
--- End of stack trace from previous location where exception was thrown ---
   at System.Runtime.ExceptionServices.ExceptionDispatchInfo.Throw()
   at System.Runtime.CompilerServices.TaskAwaiter.HandleNonSuccessAndDebuggerNotification(Task task)
   at System.Runtime.CompilerServices.TaskAwaiter`1.GetResult()
   at Plato.Stores.Users.UserStore.<CreateAsync>d__6.MoveNext() in C:\Users\Ryan\Source\Repos\plato\src\Plato.Stores\Users\UserStore.cs:line 61
--- End of stack trace from previous location where exception was thrown ---
   at System.Runtime.ExceptionServices.ExceptionDispatchInfo.Throw()
   at System.Runtime.CompilerServices.TaskAwaiter.HandleNonSuccessAndDebuggerNotification(Task task)
   at System.Runtime.CompilerServices.TaskAwaiter`1.GetResult()
   at Microsoft.AspNetCore.Identity.UserManager`1.<CreateAsync>d__73.MoveNext()
--- End of stack trace from previous location where exception was thrown ---
   at System.Runtime.ExceptionServices.ExceptionDispatchInfo.Throw()
   at System.Runtime.CompilerServices.TaskAwaiter.HandleNonSuccessAndDebuggerNotification(Task task)
   at System.Runtime.CompilerServices.TaskAwaiter`1.GetResult()
   at Microsoft.AspNetCore.Identity.UserManager`1.<CreateAsync>d__78.MoveNext()
--- End of stack trace from previous location where exception was thrown ---
   at System.Runtime.ExceptionServices.ExceptionDispatchInfo.Throw()
   at System.Runtime.CompilerServices.TaskAwaiter.HandleNonSuccessAndDebuggerNotification(Task task)
   at System.Runtime.CompilerServices.TaskAwaiter`1.GetResult()
   at Plato.Users.Services.SetUpEventHandler.<SetUp>d__3.MoveNext() in C:\Users\Ryan\Source\Repos\plato\src\Plato\Modules\Plato.Users\Services\SetUpEventHandler.cs:line 197
2018-05-26 17:41:55.006 +01:00 [Information] Microsoft.AspNetCore.Mvc.ViewFeatures.Internal.ViewResultExecutor: Executing ViewResult, running view at path /Modules/Plato.SetUp/Views/SetUp/Index.cshtml.
2018-05-26 17:41:55.016 +01:00 [Information] Microsoft.AspNetCore.Mvc.Internal.ControllerActionInvoker: Executed action Plato.SetUp.Controllers.SetUpController.Index (Plato.SetUp) in 114541.7848ms
2018-05-26 17:41:55.019 +01:00 [Information] Microsoft.AspNetCore.Hosting.Internal.WebHost: Request finished in 114567.4601ms 200 text/html; charset=utf-8
2018-05-26 17:45:30.846 +01:00 [Information] Microsoft.AspNetCore.DataProtection.KeyManagement.XmlKeyManager: User profile is available. Using 'C:\Users\Ryan\AppData\Local\ASP.NET\DataProtection-Keys' as key repository and Windows DPAPI to encrypt keys at rest.
2018-05-26 17:45:31.405 +01:00 [Information] Microsoft.AspNetCore.Hosting.Internal.WebHost: Request starting HTTP/1.1 GET http://localhost:50439/  
2018-05-26 17:45:31.405 +01:00 [Information] Microsoft.AspNetCore.Hosting.Internal.WebHost: Request starting HTTP/1.1 DEBUG http://localhost:50439/  0
2018-05-26 17:45:31.489 +01:00 [Information] Microsoft.AspNetCore.Hosting.Internal.WebHost: Request finished in 84.8357ms 200 
2018-05-26 17:45:31.512 +01:00 [Information] Plato.Hosting.DefaultPlatoHost: Start creation of shells
2018-05-26 17:45:31.666 +01:00 [Information] Plato.Hosting.DefaultPlatoHost: Done creating shells
2018-05-26 17:45:31.671 +01:00 [Information] Plato.Hosting.Web.Routing.PlatoRouterMiddleware: Begin Routing Request
2018-05-26 17:45:31.690 +01:00 [Information] Plato.Repositories.Settings.SettingRepository: Selecting all settings
2018-05-26 17:45:31.793 +01:00 [Information] Microsoft.AspNetCore.Mvc.Internal.ControllerActionInvoker: Executing action method Plato.SetUp.Controllers.SetUpController.Index (Plato.SetUp) with arguments ((null)) - ModelState is Valid
2018-05-26 17:45:31.803 +01:00 [Information] Plato.SetUp.Controllers.SetUpController: Index action on SetUp controller invoked!
2018-05-26 17:45:34.053 +01:00 [Information] Microsoft.AspNetCore.Mvc.ViewFeatures.Internal.ViewResultExecutor: Executing ViewResult, running view at path /Modules/Plato.SetUp/Views/SetUp/Index.cshtml.
2018-05-26 17:45:34.428 +01:00 [Information] Microsoft.AspNetCore.Mvc.Internal.ControllerActionInvoker: Executed action Plato.SetUp.Controllers.SetUpController.Index (Plato.SetUp) in 2644.7458ms
2018-05-26 17:45:34.435 +01:00 [Information] Microsoft.AspNetCore.Hosting.Internal.WebHost: Request finished in 3031.6091ms 200 text/html; charset=utf-8
2018-05-26 17:45:59.347 +01:00 [Information] Microsoft.AspNetCore.Hosting.Internal.WebHost: Request starting HTTP/1.1 POST http://localhost:50439/ application/x-www-form-urlencoded 402
2018-05-26 17:45:59.360 +01:00 [Information] Plato.Hosting.Web.Routing.PlatoRouterMiddleware: Begin Routing Request
2018-05-26 17:45:59.363 +01:00 [Information] Plato.Repositories.Settings.SettingRepository: Selecting all settings
2018-05-26 17:45:59.412 +01:00 [Information] Microsoft.AspNetCore.Mvc.Internal.ControllerActionInvoker: Executing action method Plato.SetUp.Controllers.SetUpController.Index (Plato.SetUp) with arguments (Plato.SetUp.ViewModels.SetUpViewModel) - ModelState is Valid
2018-05-26 17:45:59.417 +01:00 [Information] Plato.SetUp.Controllers.SetUpController: Index POST action on SetUp controller invoked!
2018-05-26 17:45:59.420 +01:00 [Information] Plato.SetUp.Controllers.SetUpController: Beginning call to SetUpAsync
2018-05-26 17:45:59.712 +01:00 [Information] Plato.Repositories.Settings.SettingRepository: Selecting all settings
2018-05-26 17:45:59.729 +01:00 [Information] Plato.Repositories.Settings.SettingRepository: Selecting all settings
2018-05-26 17:45:59.870 +01:00 [Information] Plato.Repositories.Settings.SettingRepository: Inserting settings with key: SiteSettings
2018-05-26 17:45:59.898 +01:00 [Information] Plato.Repositories.Settings.SettingRepository: Selecting setting with id: 1
2018-05-26 17:45:59.906 +01:00 [Information] Plato.Repositories.Settings.SettingRepository: Selecting all settings
2018-05-26 17:47:27.475 +01:00 [Information] Plato.SetUp.Controllers.SetUpController: Set-up of tennet 'abc' failed with the following errors...
2018-05-26 17:47:27.477 +01:00 [Information] Plato.SetUp.Controllers.SetUpController: Could not find stored procedure 'abc1_plato_sp_InsertUpdateUserSecret'.    at Plato.Data.DbContext.<>c.<ConfigureInternal>b__13_0(Object sender, DbExceptionEventArgs args) in C:\Users\Ryan\Source\Repos\plato\src\Plato.Data\DbContext.cs:line 82
   at Plato.Data.Providers.SqlProvider.HandleException(Exception x) in C:\Users\Ryan\Source\Repos\plato\src\Plato.Data\Providers\SqlProvider.cs:line 387
   at Plato.Data.Providers.SqlProvider.ExecuteScalarAsync[T](String sql, Object[] args) in C:\Users\Ryan\Source\Repos\plato\src\Plato.Data\Providers\SqlProvider.cs:line 209
   at Plato.Data.DbContext.<ExecuteScalarAsync>d__17`1.MoveNext() in C:\Users\Ryan\Source\Repos\plato\src\Plato.Data\DbContext.cs:line 135
--- End of stack trace from previous location where exception was thrown ---
   at System.Runtime.ExceptionServices.ExceptionDispatchInfo.Throw()
   at System.Runtime.CompilerServices.TaskAwaiter.HandleNonSuccessAndDebuggerNotification(Task task)
   at System.Runtime.CompilerServices.TaskAwaiter`1.GetResult()
   at Plato.Repositories.Users.UserSecretRepository.<InsertUpdateInternal>d__6.MoveNext() in C:\Users\Ryan\Source\Repos\plato\src\Plato.Repositories\Users\UserSecretRepository.cs:line 94
--- End of stack trace from previous location where exception was thrown ---
   at System.Runtime.ExceptionServices.ExceptionDispatchInfo.Throw()
   at System.Runtime.CompilerServices.TaskAwaiter.HandleNonSuccessAndDebuggerNotification(Task task)
   at System.Runtime.CompilerServices.TaskAwaiter`1.GetResult()
   at Plato.Repositories.Users.UserSecretRepository.<InsertUpdateAsync>d__4.MoveNext() in C:\Users\Ryan\Source\Repos\plato\src\Plato.Repositories\Users\UserSecretRepository.cs:line 43
--- End of stack trace from previous location where exception was thrown ---
   at System.Runtime.ExceptionServices.ExceptionDispatchInfo.Throw()
   at System.Runtime.CompilerServices.TaskAwaiter.HandleNonSuccessAndDebuggerNotification(Task task)
   at System.Runtime.CompilerServices.TaskAwaiter`1.GetResult()
   at Plato.Repositories.Users.UserRepository.<InsertUpdateAsync>d__7.MoveNext() in C:\Users\Ryan\Source\Repos\plato\src\Plato.Repositories\Users\UserRepository.cs:line 90
--- End of stack trace from previous location where exception was thrown ---
   at System.Runtime.ExceptionServices.ExceptionDispatchInfo.Throw()
   at System.Runtime.CompilerServices.TaskAwaiter.HandleNonSuccessAndDebuggerNotification(Task task)
   at System.Runtime.CompilerServices.TaskAwaiter`1.GetResult()
   at Plato.Stores.Users.UserStore.<CreateAsync>d__6.MoveNext() in C:\Users\Ryan\Source\Repos\plato\src\Plato.Stores\Users\UserStore.cs:line 61
--- End of stack trace from previous location where exception was thrown ---
   at System.Runtime.ExceptionServices.ExceptionDispatchInfo.Throw()
   at System.Runtime.CompilerServices.TaskAwaiter.HandleNonSuccessAndDebuggerNotification(Task task)
   at System.Runtime.CompilerServices.TaskAwaiter`1.GetResult()
   at Microsoft.AspNetCore.Identity.UserManager`1.<CreateAsync>d__73.MoveNext()
--- End of stack trace from previous location where exception was thrown ---
   at System.Runtime.ExceptionServices.ExceptionDispatchInfo.Throw()
   at System.Runtime.CompilerServices.TaskAwaiter.HandleNonSuccessAndDebuggerNotification(Task task)
   at System.Runtime.CompilerServices.TaskAwaiter`1.GetResult()
   at Microsoft.AspNetCore.Identity.UserManager`1.<CreateAsync>d__78.MoveNext()
--- End of stack trace from previous location where exception was thrown ---
   at System.Runtime.ExceptionServices.ExceptionDispatchInfo.Throw()
   at System.Runtime.CompilerServices.TaskAwaiter.HandleNonSuccessAndDebuggerNotification(Task task)
   at System.Runtime.CompilerServices.TaskAwaiter`1.GetResult()
   at Plato.Users.Services.SetUpEventHandler.<SetUp>d__3.MoveNext() in C:\Users\Ryan\Source\Repos\plato\src\Plato\Modules\Plato.Users\Services\SetUpEventHandler.cs:line 197
2018-05-26 17:47:27.482 +01:00 [Information] Microsoft.AspNetCore.Mvc.ViewFeatures.Internal.ViewResultExecutor: Executing ViewResult, running view at path /Modules/Plato.SetUp/Views/SetUp/Index.cshtml.
2018-05-26 17:47:27.489 +01:00 [Information] Microsoft.AspNetCore.Mvc.Internal.ControllerActionInvoker: Executed action Plato.SetUp.Controllers.SetUpController.Index (Plato.SetUp) in 88103.3875ms
2018-05-26 17:47:27.493 +01:00 [Information] Microsoft.AspNetCore.Hosting.Internal.WebHost: Request finished in 88145.8767ms 200 text/html; charset=utf-8
